<?xml version = '1.0'?>

<robot name = "ozdemre_bot" xmlns:xacro="http://www.ros.org/wiki/xacro">

<xacro:include filename="$(find ozdemre_bot)/urdf/udacity_bot.gazebo"/>
<xacro:include filename="$(find ozdemre_bot)/urdf/materials.xacro" />
<xacro:include filename="$(find ozdemre_bot)/urdf/ozdemre_bot_sim.gazebo" />

	<link name="robot_footprint"></link>

	<joint name="robot_footprint_joint" type="fixed">
		<origin xyz="0 0 0" rpy="0 0 0" />
		<parent link="robot_footprint" />
		<child link="chasis" />
	</joint>

	<link name="chasis">
		<pose>0 0 0.4 0 0 0</pose>
	
		<inertial>
			<mass value="5.0" />
			<origin xyz="0 0 0" rpy="0 0 0" />
			<inertia
				ixx="0.1" ixy="0" ixz="0"
				iyy="0.1" iyz="0"
				izz="0.1"
			/>
		</inertial>

		<collision name="chasis_collision">
			<origin xyz="0 0 0" rpy="0 0 0" />
			<geometry>
				<box size="0.4 0.2 0.2" />
			</geometry>
		</collision>

		<visual name="chasis_visual">
			<origin xyz="0 0 0" rpy="0 0 0" />
			<geometry>
				<box size="0.4 0.2 0.2" />
			</geometry>
      <material
        name="blue"/>
		</visual>

	</link>


	<link name='left_wheel'>
    <pose>0 0 0 0 0 0</pose>

    <inertial>
      <mass value="1.0"/>
      <origin xyz="0 0 0" rpy="0 1.5707 1.5707"/>
      <inertia
          ixx="0.1" ixy="0" ixz="0"
          iyy="0.1" iyz="0"
          izz="0.1"
      />
    </inertial>

    <collision name='left_wheel_collision'>
      <origin xyz="0 0 0" rpy="0 1.5707 1.5707"/> 
      <geometry>
        <cylinder radius="0.05" length="0.02"/>
      </geometry>
    </collision>

    <visual name='left_wheel_visual'>
      <origin xyz="0 0 0" rpy="0 1.5707 1.5707"/>
      <geometry>
        <cylinder radius="0.05" length="0.02"/>
      </geometry>
    </visual>

  </link>

	<link name='right_wheel'>
    <pose>0 0 0 0 0 0</pose>

    <inertial>
      <mass value="1.0"/>
      <origin xyz="0 0 0" rpy="0 1.5707 1.5707"/>
      <inertia
          ixx="0.1" ixy="0" ixz="0"
          iyy="0.1" iyz="0"
          izz="0.1"
      />
    </inertial>

    <collision name='right_wheel_collision'>
      <origin xyz="0 0 0" rpy="0 1.5707 1.5707"/> 
      <geometry>
        <cylinder radius="0.05" length="0.02"/>
      </geometry>
    </collision>

    <visual name='right_wheel_visual'>
      <origin xyz="0 0 0" rpy="0 1.5707 1.5707"/>
      <geometry>
        <cylinder radius="0.05" length="0.02"/>
      </geometry>
    </visual>

  </link>

	<link name='left_caster_mid'>
    <pose>0 0 0 0 0 0</pose>

    <inertial>
      <mass value="0.1"/>
      <origin xyz="0 0 0" rpy="0 0 0"/>
      <inertia
          ixx="0.001" ixy="0" ixz="0"
          iyy="0.001" iyz="0"
          izz="0.001"
      />
    </inertial>

    <collision name='left_caster_mid_collision'>
      <origin xyz="0 0 0" rpy="0 0 0"/> 
      <geometry>
        <cylinder radius="0.01" length="0.03"/>
      </geometry>
    </collision>

    <visual name='left_caster_mid_visual'>
      <origin xyz="0 0 0" rpy="0 0 0"/>
      <geometry>
        <cylinder radius="0.01" length="0.03"/>
      </geometry>
    </visual>

  </link>

	<link name='right_caster_mid'>
    <pose>0 0 0 0 0 0</pose>

    <inertial>
      <mass value="0.1"/>
      <origin xyz="0 0 0" rpy="0 0 0"/>
      <inertia
          ixx="0.001" ixy="0" ixz="0"
          iyy="0.001" iyz="0"
          izz="0.001"
      />
    </inertial>

    <collision name='right_caster_mid_collision'>
      <origin xyz="0 0 0" rpy="0 0 0"/> 
      <geometry>
        <cylinder radius="0.01" length="0.03"/>
      </geometry>
    </collision>

    <visual name='right_caster_mid_visual'>
      <origin xyz="0 0 0" rpy="0 0 0"/>
      <geometry>
        <cylinder radius="0.01" length="0.03"/>
      </geometry>
    </visual>

  </link>

	<link name='left_caster_wheel'>
    <pose>0 0 0 0 0 0</pose>

    <inertial>
      <mass value="0.05"/>
      <origin xyz="0 0 0" rpy="0 1.5707 1.5707"/>
      <inertia
          ixx="0.001" ixy="0" ixz="0"
          iyy="0.001" iyz="0"
          izz="0.001"
      />
    </inertial>

    <collision name='left_caster_wheel_collision'>
      <origin xyz="0 0 0" rpy="0 1.5707 1.5707"/> 
      <geometry>
        <cylinder radius="0.01" length="0.01"/>
      </geometry>
    </collision>

    <visual name='left_caster_wheel_visual'>
      <origin xyz="0 0 0" rpy="0 1.5707 1.5707"/>
      <geometry>
        <cylinder radius="0.01" length="0.01"/>
      </geometry>
    </visual>

  </link>

	<link name='right_caster_wheel'>
    <pose>0 0 0 0 0 0</pose>

    <inertial>
      <mass value="0.05"/>
      <origin xyz="0 0 0" rpy="0 1.5707 1.5707"/>
      <inertia
          ixx="0.001" ixy="0" ixz="0"
          iyy="0.001" iyz="0"
          izz="0.001"
      />
    </inertial>

    <collision name='right_caster_wheel_collision'>
      <origin xyz="0 0 0" rpy="0 1.5707 1.5707"/> 
      <geometry>
        <cylinder radius="0.01" length="0.01"/>
      </geometry>
    </collision>

    <visual name='right_caster_wheel_visual'>
      <origin xyz="0 0 0" rpy="0 1.5707 1.5707"/>
      <geometry>
        <cylinder radius="0.01" length="0.01"/>
      </geometry>
    </visual>

  </link>

  <link name='camera'>
    <pose>0 0 0 0 0 0</pose>

    <inertial>
      <mass value="0.1"/>
      <origin xyz="0 0 0" rpy="0 0 0"/>
      <inertia
          ixx="1e-6" ixy="0" ixz="0"
          iyy="1e-6" iyz="0"
          izz="1e-6"
      />
    </inertial>

    <collision name='camera_collision'>
      <origin xyz="0 0 0" rpy="0 0 0"/> 
      <geometry>
		<box size="0.05 0.05 0.05"/>
      </geometry>
    </collision>

    <visual name='camera_visual'>
      <origin xyz="0 0 0" rpy="0 0 0"/>
      <geometry>
		<box size="0.05 0.05 0.05"/>
      </geometry>
    </visual>

  </link>
  
  <link name='hokuyo'>
    <pose>0 0 0 0 0 0</pose>

    <inertial>
      <mass value="0.1"/>
      <origin xyz="0 0 0" rpy="0 0 0"/>
      <inertia
          ixx="1e-6" ixy="0" ixz="0"
          iyy="1e-6" iyz="0"
          izz="1e-6"
      />
    </inertial>

    <collision name='hokuyo_collision'>
      <origin xyz="0 0 0" rpy="0 0 0"/> 
      <geometry>
		<box size="0.1 0.1 0.1"/>
      </geometry>
    </collision>

    <visual name='hokuyo_visual'>
      <origin xyz="0 0 0" rpy="0 0 0"/>
      <geometry>
		<mesh filename="package://ozdemre_bot/meshes/hokuyo.dae"/>
      </geometry>
    </visual>

  </link>



	<joint type="continuous" name="left_wheel_hinge">
    <origin xyz="-0.13 0.1 -0.09" rpy="0 0 0"/>
    <child link="left_wheel"/>
    <parent link="chasis"/>
    <axis xyz="0 1 0" rpy="0 0 0"/>
    <limit effort="10000" velocity="1000"/>
    <dynamics damping="1.0" friction="1.0"/>
  </joint>
  
  <joint type="continuous" name="right_wheel_hinge">
    <origin xyz="-0.13 -0.1 -0.09" rpy="0 0 0"/>
    <child link="right_wheel"/>
    <parent link="chasis"/>
    <axis xyz="0 1 0" rpy="0 0 0"/>
    <limit effort="10000" velocity="1000"/>
    <dynamics damping="1.0" friction="1.0"/>
  </joint>

  <joint type="continuous" name="left_caster_mid_hinge">
    <origin xyz="0.15 0.09 -0.115" rpy="0 0 0"/>
    <child link="left_caster_mid"/>
    <parent link="chasis"/>
    <axis xyz="0 0 1" rpy="0 0 0"/>
    <!--limit effort="10000" velocity="1000"/>
    <dynamics damping="1.0" friction="1.0"/-->
  </joint>

  <joint type="continuous" name="right_caster_mid_hinge">
    <origin xyz="0.15 -0.09 -0.115" rpy="0 0 0"/>
    <child link="right_caster_mid"/>
    <parent link="chasis"/>
    <axis xyz="0 0 1" rpy="0 0 0"/>
    <!--limit effort="10000" velocity="1000"/>
    <dynamics damping="1.0" friction="1.0"/-->
  </joint>

	<joint type="continuous" name="left_caster_wheel_hinge">
    <origin xyz="-0.02 0 -0.015" rpy="0 0 0"/>
    <child link="left_caster_wheel"/>
    <parent link="left_caster_mid"/>
    <axis xyz="0 1 0" rpy="0 0 0"/>
    <!--limit effort="10000" velocity="1000"/>
    <dynamics damping="1.0" friction="1.0"/-->
  </joint>

	<joint type="continuous" name="right_caster_wheel_hinge">
    <origin xyz="-0.02 0 -0.015" rpy="0 0 0"/>
    <child link="right_caster_wheel"/>
    <parent link="right_caster_mid"/>
    <axis xyz="0 1 0" rpy="0 0 0"/>
    <!--limit effort="10000" velocity="1000"/>
    <dynamics damping="1.0" friction="1.0"/-->
  </joint>

  <joint type="fixed" name="camera_joint">
    <origin xyz="0.201 0 0" rpy="0 0 0"/>
    <child link="camera"/>
    <parent link="chasis"/>
  </joint>
  
  <joint type="fixed" name="hokuyo_joint">
    <origin xyz="0.2 0 0.1" rpy="0 0 0"/>
    <child link="hokuyo"/>
    <parent link="chasis"/>
  </joint>

</robot>
