<?xml version='1.0'?>

<robot name="udacity_bot" xmlns:xacro="http://www.ros.org/wiki/xacro">

  <xacro:include filename="$(find ozdemre_bot)/urdf/udacity_bot.gazebo" />

  <link name="robot_footprint"></link>

  <joint name="robot_footprint_joint" type="fixed">
    <origin xyz="0 0 0" rpy="0 0 0" />
    <parent link="robot_footprint"/>
    <child link="chassis" />
  </joint>

  <link name='chassis'>
    <pose>0 0 0.1 0 0 0</pose>

    <inertial>
      <mass value="15.0"/>
      <origin xyz="0.0 0 0" rpy=" 0 0 0"/>
      <inertia
          ixx="0.1" ixy="0" ixz="0"
          iyy="0.1" iyz="0"
          izz="0.1"
      />
    </inertial>

    <collision name='collision'>
      <origin xyz="0 0 0" rpy=" 0 0 0"/> 
      <geometry>
        <box size=".4 .2 .1"/>
      </geometry>
    </collision>

    <visual name='chassis_visual'>
      <origin xyz="0 0 0" rpy=" 0 0 0"/>
      <geometry>
        <box size=".4 .2 .1"/>
      </geometry>
    </visual>


    <collision name='back_caster_collision'>
      <origin xyz="-0.15 0 -0.05" rpy=" 0 0 0"/>
      <geometry>
        <sphere radius="0.0499"/>
      </geometry>
      <surface>
        <friction>
          <ode>
            <mu>0</mu>
            <mu2>0</mu2>
            <slip1>1.0</slip1>
            <slip2>1.0</slip2>
          </ode>
        </friction>
      </surface>
    </collision>

    <visual name='back_caster_visual'>
      <origin xyz="-0.15 0 -0.05" rpy=" 0 0 0"/>
      <geometry>
        <sphere radius="0.05"/>
      </geometry>
    </visual>

    <collision name='front_caster_collision'>
      <origin xyz="0.15 0 -0.05" rpy=" 0 0 0"/>
      <geometry>
        <sphere radius="0.0499"/>
      </geometry>
      <surface>
        <friction>
          <ode>
            <mu>0</mu>
            <mu2>0</mu2>
            <slip1>1.0</slip1>
            <slip2>1.0</slip2>
          </ode>
        </friction>
      </surface>
    </collision>

    <visual name='front_caster_visual'>
      <origin xyz="0.15 0 -0.05" rpy=" 0 0 0"/>
      <geometry>
        <sphere radius="0.05"/>
      </geometry>
    </visual>

    <collision name='lidar_bracket_collision'>
      <origin xyz="0.225 0 -0.0225" rpy=" 0 0 0"/>
      <geometry>
        <box size="0.05 0.05 -0.01"/>
      </geometry>
    </collision>

    <visual name='lidar_bracket_visual'>
      <origin xyz="0.225 0 -0.0225" rpy=" 0 0 0"/>
      <geometry>
        <box size="0.05 0.05 0.01"/>
      </geometry>
    </visual>

    <collision name='passenger_collision'>
      <origin xyz="0 0 0.05" rpy=" 0 0 0"/>
      <geometry>
        <box size=".2 .2 .1"/>
      </geometry>
    </collision>

    <visual name='passenger_visual'>
      <origin xyz="0 0 0.05" rpy=" 0 0 0"/>
      <geometry>
        <box size=".2 .2 .1"/>
      </geometry>
    </visual>

    <collision name='column1_collision'>
      <origin xyz="-0.18 0.08 0.05" rpy=" 0 0 0"/>
      <geometry>
        <box size="0.02 0.02 0.13"/>
      </geometry>
    </collision>

    <visual name='column1_visual'>
      <origin xyz="-0.18 0.08 0.05" rpy=" 0 0 0"/>
      <geometry>
        <box size="0.02 0.02 0.13"/>
      </geometry>
    </visual>

    <collision name='column2_collision'>
      <origin xyz="-0.18 -0.08 0.05" rpy=" 0 0 0"/>
      <geometry>
        <box size="0.02 0.02 0.13"/>
      </geometry>
    </collision>

    <visual name='column2_visual'>
      <origin xyz="-0.18 -0.08 0.05" rpy=" 0 0 0"/>
      <geometry>
        <box size="0.02 0.02 0.13"/>
      </geometry>
    </visual>

    <collision name='spoiler_collision'>
      <origin xyz="-0.18 0 0.13" rpy=" 0 0.78 0"/>
      <geometry>
        <box size="0.05 .2 .01"/>
      </geometry>
    </collision>

    <visual name='spoiler_visual'>
      <origin xyz="-0.18 0 0.13" rpy=" 0 0.78 0"/>
      <geometry>
        <box size="0.05 .2 .01"/>
      </geometry>
    </visual>

  </link>

  <link name="left_wheel">
    <inertial>
      <mass value="5.0"/>
      <origin xyz="0 0 0" rpy=" 0 1.5707 1.5707"/> 
      <inertia
          ixx="0.1" ixy="0" ixz="0"
          iyy="0.1" iyz="0"
          izz="0.1"
      />
    </inertial>

    <collision name='left_wheel_collision'>
      <origin xyz="0 0 0" rpy=" 0 1.5707 1.5707"/> 
      <geometry>
        <cylinder radius="0.1" length="0.05" />
      </geometry>
    </collision>

    <visual name='left_wheel_visual'>
      <origin xyz="0 0 0" rpy=" 0 1.5707 1.5707"/> 
      <geometry>
        <cylinder radius="0.1" length="0.05" />
      </geometry>
    </visual>
  </link>

  <link name="right_wheel">
    <inertial>
      <mass value="5.0"/>
      <origin xyz="0 0 0" rpy=" 0 1.5707 1.5707"/> 
      <inertia
          ixx="0.1" ixy="0" ixz="0"
          iyy="0.1" iyz="0"
          izz="0.1"
      />
    </inertial>

    <collision name='right_wheel_collision'>
      <origin xyz="0 0 0" rpy=" 0 1.5707 1.5707"/> 
      <geometry>
        <cylinder radius="0.1" length="0.05" />
      </geometry>
    </collision>

    <visual name='right_wheel_visual'>
      <origin xyz="0 0 0" rpy=" 0 1.5707 1.5707"/> 
      <geometry>
        <cylinder radius="0.1" length="0.05" />
      </geometry>
    </visual>
  </link>

  <joint type="continuous" name="left_wheel_hinge">
    <origin xyz="0 0.15 0" rpy="0 0 0"/>
    <child link="left_wheel"/>
    <parent link="chassis"/>
    <axis xyz="0 1 0" rpy="0 0 0"/>
    <limit effort="10000" velocity="1000"/>
    <joint_properties damping="1.0" friction="1.0"/>
  </joint>

  <joint type="continuous" name="right_wheel_hinge">
    <origin xyz="0 -0.15 0" rpy="0 0 0"/>
    <child link="right_wheel"/>
    <parent link="chassis"/>
    <axis xyz="0 1 0" rpy="0 0 0"/>
    <limit effort="10000" velocity="1000"/>
    <joint_properties damping="1.0" friction="1.0"/>
  </joint>

  <link name="camera">
    <inertial>
      <mass value=".1"/>
      <origin xyz="0 0 0" rpy="0 0 0"/> 
      <inertia
          ixx="1e-6" ixy="0" ixz="0"
          iyy="1e-6" iyz="0"
          izz="1e-6"
      />
    </inertial>

    <collision name='camera_collision'>
      <origin xyz="0 0 0" rpy="0 0 0"/> 
      <geometry>
        <box size="0.0225 0.075 0.0225"/>
      </geometry>
    </collision>

    <visual name='camera_visual'>
      <origin xyz="0 0 0" rpy="0 0 0"/> 
      <geometry>
        <box size="0.0225 0.075 0.0225"/>
      </geometry>
    </visual>
  </link>

  <joint type="fixed" name="camera_joint">
    <origin xyz="0.2 0 0.03" rpy="0 0 0"/>
    <child link="camera"/>
    <parent link="chassis"/>
  </joint>

  <link name="hokuyo">
    <inertial>
      <mass value=".1"/>
      <origin xyz="0 0 0" rpy="0 0 0"/> 
      <inertia
          ixx="1e-6" ixy="0" ixz="0"
          iyy="1e-6" iyz="0"
          izz="1e-6"
      />
    </inertial>

    <collision name='hokuyo_collision'>
      <origin xyz="0 0 0" rpy="0 0 0"/> 
      <geometry>
        <box size="0.1 0.1 0.1"/>
      </geometry>
    </collision>

    <visual name='hokuyo_visual'>
      <origin xyz="0 0 0" rpy="0 0 0"/> 
      <geometry>
        <mesh filename="package://ozdemre_bot/meshes/hokuyo.dae"/>
      </geometry>
    </visual>
  </link>

  <joint type="fixed" name="hokuyo_joint">
    <origin xyz="0.225 0 -0.0225" rpy="0 0 0"/>
    <child link="hokuyo"/>
    <parent link="chassis"/>
  </joint>

</robot>
